Traceback (most recent call last):
  File "/Users/jiemin/Documents/cmu/tasks/task06_SoftwareDesign/back-end/obs-v2/devobs/views.py", line 64, in login_auth
    username = request.json['username']
TypeError: 'NoneType' object has no attribute '__getitem__'

Traceback (most recent call last):
  File "/Users/jiemin/Documents/cmu/tasks/task06_SoftwareDesign/back-end/obs-v2/devobs/views.py", line 66, in login_auth
    user = Users.query.filter_by(username=username).first()
  File "/Users/jiemin/Documents/cmu/tasks/task06_SoftwareDesign/back-end/obs-v2/flask-env/lib/python2.7/site-packages/flask_sqlalchemy/__init__.py", line 512, in __get__
    mapper = orm.class_mapper(type)
  File "/Users/jiemin/Documents/cmu/tasks/task06_SoftwareDesign/back-end/obs-v2/flask-env/lib/python2.7/site-packages/sqlalchemy/orm/base.py", line 421, in class_mapper
    mapper = _inspect_mapped_class(class_, configure=configure)
  File "/Users/jiemin/Documents/cmu/tasks/task06_SoftwareDesign/back-end/obs-v2/flask-env/lib/python2.7/site-packages/sqlalchemy/orm/base.py", line 400, in _inspect_mapped_class
    mapper._configure_all()
  File "/Users/jiemin/Documents/cmu/tasks/task06_SoftwareDesign/back-end/obs-v2/flask-env/lib/python2.7/site-packages/sqlalchemy/orm/mapper.py", line 1223, in _configure_all
    configure_mappers()
  File "/Users/jiemin/Documents/cmu/tasks/task06_SoftwareDesign/back-end/obs-v2/flask-env/lib/python2.7/site-packages/sqlalchemy/orm/mapper.py", line 2873, in configure_mappers
    mapper._post_configure_properties()
  File "/Users/jiemin/Documents/cmu/tasks/task06_SoftwareDesign/back-end/obs-v2/flask-env/lib/python2.7/site-packages/sqlalchemy/orm/mapper.py", line 1766, in _post_configure_properties
    prop.init()
  File "/Users/jiemin/Documents/cmu/tasks/task06_SoftwareDesign/back-end/obs-v2/flask-env/lib/python2.7/site-packages/sqlalchemy/orm/interfaces.py", line 184, in init
    self.do_init()
  File "/Users/jiemin/Documents/cmu/tasks/task06_SoftwareDesign/back-end/obs-v2/flask-env/lib/python2.7/site-packages/sqlalchemy/orm/relationships.py", line 1654, in do_init
    self._setup_join_conditions()
  File "/Users/jiemin/Documents/cmu/tasks/task06_SoftwareDesign/back-end/obs-v2/flask-env/lib/python2.7/site-packages/sqlalchemy/orm/relationships.py", line 1729, in _setup_join_conditions
    can_be_synced_fn=self._columns_are_mapped
  File "/Users/jiemin/Documents/cmu/tasks/task06_SoftwareDesign/back-end/obs-v2/flask-env/lib/python2.7/site-packages/sqlalchemy/orm/relationships.py", line 1996, in __init__
    self._determine_joins()
  File "/Users/jiemin/Documents/cmu/tasks/task06_SoftwareDesign/back-end/obs-v2/flask-env/lib/python2.7/site-packages/sqlalchemy/orm/relationships.py", line 2123, in _determine_joins
    % self.prop)
AmbiguousForeignKeysError: Could not determine join condition between parent/child tables on relationship Account.transfers - there are multiple foreign key paths linking the tables.  Specify the 'foreign_keys' argument, providing a list of those columns which should be counted as containing a foreign key reference to the parent table.

Traceback (most recent call last):
  File "/Users/jiemin/Documents/cmu/tasks/task06_SoftwareDesign/back-end/obs-v2/devobs/views.py", line 66, in login_auth
    user = Users.query.filter_by(username=username).first()
  File "/Users/jiemin/Documents/cmu/tasks/task06_SoftwareDesign/back-end/obs-v2/flask-env/lib/python2.7/site-packages/flask_sqlalchemy/__init__.py", line 512, in __get__
    mapper = orm.class_mapper(type)
  File "/Users/jiemin/Documents/cmu/tasks/task06_SoftwareDesign/back-end/obs-v2/flask-env/lib/python2.7/site-packages/sqlalchemy/orm/base.py", line 421, in class_mapper
    mapper = _inspect_mapped_class(class_, configure=configure)
  File "/Users/jiemin/Documents/cmu/tasks/task06_SoftwareDesign/back-end/obs-v2/flask-env/lib/python2.7/site-packages/sqlalchemy/orm/base.py", line 400, in _inspect_mapped_class
    mapper._configure_all()
  File "/Users/jiemin/Documents/cmu/tasks/task06_SoftwareDesign/back-end/obs-v2/flask-env/lib/python2.7/site-packages/sqlalchemy/orm/mapper.py", line 1223, in _configure_all
    configure_mappers()
  File "/Users/jiemin/Documents/cmu/tasks/task06_SoftwareDesign/back-end/obs-v2/flask-env/lib/python2.7/site-packages/sqlalchemy/orm/mapper.py", line 2870, in configure_mappers
    raise e
InvalidRequestError: One or more mappers failed to initialize - can't proceed with initialization of other mappers. Triggering mapper: 'Mapper|Account|account'. Original exception was: Could not determine join condition between parent/child tables on relationship Account.transfers - there are multiple foreign key paths linking the tables.  Specify the 'foreign_keys' argument, providing a list of those columns which should be counted as containing a foreign key reference to the parent table.

Traceback (most recent call last):
  File "/Users/jiemin/Documents/cmu/tasks/task06_SoftwareDesign/back-end/obs-v2/devobs/views.py", line 66, in login_auth
    user = Users.query.filter_by(user_name=username).first()
  File "/Users/jiemin/Documents/cmu/tasks/task06_SoftwareDesign/back-end/obs-v2/flask-env/lib/python2.7/site-packages/flask_sqlalchemy/__init__.py", line 512, in __get__
    mapper = orm.class_mapper(type)
  File "/Users/jiemin/Documents/cmu/tasks/task06_SoftwareDesign/back-end/obs-v2/flask-env/lib/python2.7/site-packages/sqlalchemy/orm/base.py", line 421, in class_mapper
    mapper = _inspect_mapped_class(class_, configure=configure)
  File "/Users/jiemin/Documents/cmu/tasks/task06_SoftwareDesign/back-end/obs-v2/flask-env/lib/python2.7/site-packages/sqlalchemy/orm/base.py", line 400, in _inspect_mapped_class
    mapper._configure_all()
  File "/Users/jiemin/Documents/cmu/tasks/task06_SoftwareDesign/back-end/obs-v2/flask-env/lib/python2.7/site-packages/sqlalchemy/orm/mapper.py", line 1223, in _configure_all
    configure_mappers()
  File "/Users/jiemin/Documents/cmu/tasks/task06_SoftwareDesign/back-end/obs-v2/flask-env/lib/python2.7/site-packages/sqlalchemy/orm/mapper.py", line 2873, in configure_mappers
    mapper._post_configure_properties()
  File "/Users/jiemin/Documents/cmu/tasks/task06_SoftwareDesign/back-end/obs-v2/flask-env/lib/python2.7/site-packages/sqlalchemy/orm/mapper.py", line 1766, in _post_configure_properties
    prop.init()
  File "/Users/jiemin/Documents/cmu/tasks/task06_SoftwareDesign/back-end/obs-v2/flask-env/lib/python2.7/site-packages/sqlalchemy/orm/interfaces.py", line 184, in init
    self.do_init()
  File "/Users/jiemin/Documents/cmu/tasks/task06_SoftwareDesign/back-end/obs-v2/flask-env/lib/python2.7/site-packages/sqlalchemy/orm/relationships.py", line 1654, in do_init
    self._setup_join_conditions()
  File "/Users/jiemin/Documents/cmu/tasks/task06_SoftwareDesign/back-end/obs-v2/flask-env/lib/python2.7/site-packages/sqlalchemy/orm/relationships.py", line 1729, in _setup_join_conditions
    can_be_synced_fn=self._columns_are_mapped
  File "/Users/jiemin/Documents/cmu/tasks/task06_SoftwareDesign/back-end/obs-v2/flask-env/lib/python2.7/site-packages/sqlalchemy/orm/relationships.py", line 1996, in __init__
    self._determine_joins()
  File "/Users/jiemin/Documents/cmu/tasks/task06_SoftwareDesign/back-end/obs-v2/flask-env/lib/python2.7/site-packages/sqlalchemy/orm/relationships.py", line 2123, in _determine_joins
    % self.prop)
AmbiguousForeignKeysError: Could not determine join condition between parent/child tables on relationship Account.transfers - there are multiple foreign key paths linking the tables.  Specify the 'foreign_keys' argument, providing a list of those columns which should be counted as containing a foreign key reference to the parent table.

Traceback (most recent call last):
  File "/Users/jiemin/Documents/cmu/tasks/task06_SoftwareDesign/back-end/obs-v2/devobs/views.py", line 66, in login_auth
    user = Users.query.filter_by(username=username).first()
  File "/Users/jiemin/Documents/cmu/tasks/task06_SoftwareDesign/back-end/obs-v2/flask-env/lib/python2.7/site-packages/flask_sqlalchemy/__init__.py", line 512, in __get__
    mapper = orm.class_mapper(type)
  File "/Users/jiemin/Documents/cmu/tasks/task06_SoftwareDesign/back-end/obs-v2/flask-env/lib/python2.7/site-packages/sqlalchemy/orm/base.py", line 421, in class_mapper
    mapper = _inspect_mapped_class(class_, configure=configure)
  File "/Users/jiemin/Documents/cmu/tasks/task06_SoftwareDesign/back-end/obs-v2/flask-env/lib/python2.7/site-packages/sqlalchemy/orm/base.py", line 400, in _inspect_mapped_class
    mapper._configure_all()
  File "/Users/jiemin/Documents/cmu/tasks/task06_SoftwareDesign/back-end/obs-v2/flask-env/lib/python2.7/site-packages/sqlalchemy/orm/mapper.py", line 1223, in _configure_all
    configure_mappers()
  File "/Users/jiemin/Documents/cmu/tasks/task06_SoftwareDesign/back-end/obs-v2/flask-env/lib/python2.7/site-packages/sqlalchemy/orm/mapper.py", line 2873, in configure_mappers
    mapper._post_configure_properties()
  File "/Users/jiemin/Documents/cmu/tasks/task06_SoftwareDesign/back-end/obs-v2/flask-env/lib/python2.7/site-packages/sqlalchemy/orm/mapper.py", line 1766, in _post_configure_properties
    prop.init()
  File "/Users/jiemin/Documents/cmu/tasks/task06_SoftwareDesign/back-end/obs-v2/flask-env/lib/python2.7/site-packages/sqlalchemy/orm/interfaces.py", line 184, in init
    self.do_init()
  File "/Users/jiemin/Documents/cmu/tasks/task06_SoftwareDesign/back-end/obs-v2/flask-env/lib/python2.7/site-packages/sqlalchemy/orm/relationships.py", line 1654, in do_init
    self._setup_join_conditions()
  File "/Users/jiemin/Documents/cmu/tasks/task06_SoftwareDesign/back-end/obs-v2/flask-env/lib/python2.7/site-packages/sqlalchemy/orm/relationships.py", line 1729, in _setup_join_conditions
    can_be_synced_fn=self._columns_are_mapped
  File "/Users/jiemin/Documents/cmu/tasks/task06_SoftwareDesign/back-end/obs-v2/flask-env/lib/python2.7/site-packages/sqlalchemy/orm/relationships.py", line 1996, in __init__
    self._determine_joins()
  File "/Users/jiemin/Documents/cmu/tasks/task06_SoftwareDesign/back-end/obs-v2/flask-env/lib/python2.7/site-packages/sqlalchemy/orm/relationships.py", line 2123, in _determine_joins
    % self.prop)
AmbiguousForeignKeysError: Could not determine join condition between parent/child tables on relationship Transfer.from_account_class - there are multiple foreign key paths linking the tables.  Specify the 'foreign_keys' argument, providing a list of those columns which should be counted as containing a foreign key reference to the parent table.

Traceback (most recent call last):
  File "/Users/jiemin/Documents/cmu/tasks/task06_SoftwareDesign/back-end/obs-v2/devobs/views.py", line 68, in login_auth
    login_user(user)
  File "/Users/jiemin/Documents/cmu/tasks/task06_SoftwareDesign/back-end/obs-v2/flask-env/lib/python2.7/site-packages/flask_login/utils.py", line 140, in login_user
    user_id = getattr(user, current_app.login_manager.id_attribute)()
  File "/Users/jiemin/Documents/cmu/tasks/task06_SoftwareDesign/back-end/obs-v2/devobs/models.py", line 24, in get_id
    return unicode(self.id)
AttributeError: 'Users' object has no attribute 'id'

test logging
test logging
test logging
test logging
test logging
test logging
test logging
test logging
test logging
test logging
test logging
test logging
test logging
test logging
test logging
test logging
test logging
test logging
test logging
test logging
test logging
test logging
test logging
test logging
test logging
test logging
test logging
test logging
test logging
test logging
test logging
test logging
test logging
test logging
test logging
test logging
test logging
test logging
test logging
test logging
test logging
test logging
test logging
test logging
test logging
test logging
test logging
test logging
test logging
test logging
test logging
Traceback (most recent call last):
  File "/Users/jiemin/Documents/cmu/tasks/task06_SoftwareDesign/back-end/obs-v2/devobs/views.py", line 109, in get_transactions
    transactions = db.session.query(Transaction).filter(account_num=account_num).all()
TypeError: filter() got an unexpected keyword argument 'account_num'

Traceback (most recent call last):
  File "/Users/jiemin/Documents/cmu/tasks/task06_SoftwareDesign/back-end/obs-v2/devobs/views.py", line 109, in get_transactions
    transactions = db.session.query(Transaction).filter(account_num=account_num).all()
TypeError: filter() got an unexpected keyword argument 'account_num'

Traceback (most recent call last):
  File "/Users/jiemin/Documents/cmu/tasks/task06_SoftwareDesign/back-end/obs-v2/devobs/views.py", line 109, in get_transactions
    transactions = db.session.query(Transaction).filter(account_num=account_num).all()
TypeError: filter() got an unexpected keyword argument 'account_num'

Traceback (most recent call last):
  File "/Users/jiemin/Documents/cmu/tasks/task06_SoftwareDesign/back-end/obs-v2/devobs/views.py", line 109, in get_transactions
    transactions = db.session.query(Transaction).filter(account_num=account_num1)
TypeError: filter() got an unexpected keyword argument 'account_num'

Traceback (most recent call last):
  File "/Users/jiemin/Documents/cmu/tasks/task06_SoftwareDesign/back-end/obs-v2/devobs/views.py", line 110, in get_transactions
    result['data'] = jsonify(transactions)
  File "/Users/jiemin/Documents/cmu/tasks/task06_SoftwareDesign/back-end/obs-v2/flask-env/lib/python2.7/site-packages/flask/json.py", line 263, in jsonify
    (dumps(data, indent=indent, separators=separators), '\n'),
  File "/Users/jiemin/Documents/cmu/tasks/task06_SoftwareDesign/back-end/obs-v2/flask-env/lib/python2.7/site-packages/flask/json.py", line 123, in dumps
    rv = _json.dumps(obj, **kwargs)
  File "/System/Library/Frameworks/Python.framework/Versions/2.7/lib/python2.7/json/__init__.py", line 250, in dumps
    sort_keys=sort_keys, **kw).encode(obj)
  File "/System/Library/Frameworks/Python.framework/Versions/2.7/lib/python2.7/json/encoder.py", line 209, in encode
    chunks = list(chunks)
  File "/System/Library/Frameworks/Python.framework/Versions/2.7/lib/python2.7/json/encoder.py", line 442, in _iterencode
    o = _default(o)
  File "/Users/jiemin/Documents/cmu/tasks/task06_SoftwareDesign/back-end/obs-v2/flask-env/lib/python2.7/site-packages/flask/json.py", line 80, in default
    return _json.JSONEncoder.default(self, o)
  File "/System/Library/Frameworks/Python.framework/Versions/2.7/lib/python2.7/json/encoder.py", line 184, in default
    raise TypeError(repr(o) + " is not JSON serializable")
TypeError: <flask_sqlalchemy.BaseQuery object at 0x1117e07d0> is not JSON serializable

Traceback (most recent call last):
  File "/Users/jiemin/Documents/cmu/tasks/task06_SoftwareDesign/back-end/obs-v2/devobs/views.py", line 139, in transfer_funds
    from_account = g.user.accounts.filter_by(Account.account_num == fromacnt)
TypeError: filter_by() takes exactly 1 argument (2 given)

Traceback (most recent call last):
  File "/Users/jiemin/Documents/cmu/tasks/task06_SoftwareDesign/back-end/obs-v2/devobs/views.py", line 139, in transfer_funds
    from_account = g.user.accounts.filter_by(Account.account_num == fromacnt)
TypeError: filter_by() takes exactly 1 argument (2 given)

Traceback (most recent call last):
  File "/Users/jiemin/Documents/cmu/tasks/task06_SoftwareDesign/back-end/obs-v2/devobs/views.py", line 139, in transfer_funds
    from_account = g.user.accounts.filter_by(Account.account_num == fromacnt)
TypeError: filter_by() takes exactly 1 argument (2 given)

Traceback (most recent call last):
  File "/Users/jiemin/Documents/cmu/tasks/task06_SoftwareDesign/back-end/obs-v2/devobs/views.py", line 139, in transfer_funds
    from_account = g.user.accounts.filter_by(Account.account_num == fromacnt)
TypeError: filter_by() takes exactly 1 argument (2 given)

Traceback (most recent call last):
  File "/Users/jiemin/Documents/cmu/tasks/task06_SoftwareDesign/back-end/obs-v2/devobs/views.py", line 139, in transfer_funds
    from_account = g.user.accounts.filter_by(Account.account_num == fromacnt)
TypeError: filter_by() takes exactly 1 argument (2 given)

Traceback (most recent call last):
  File "/Users/jiemin/Documents/cmu/tasks/task06_SoftwareDesign/back-end/obs-v2/devobs/views.py", line 139, in transfer_funds
    from_account = g.user.accounts.filter_by(Account.account_num == fromacnt)
TypeError: filter_by() takes exactly 1 argument (2 given)

Traceback (most recent call last):
  File "/Users/jiemin/Documents/cmu/tasks/task06_SoftwareDesign/back-end/obs-v2/devobs/views.py", line 139, in transfer_funds
    print(g.user.accounts)
  File "/Users/jiemin/Documents/cmu/tasks/task06_SoftwareDesign/back-end/obs-v2/flask-env/lib/python2.7/site-packages/werkzeug/local.py", line 347, in __getattr__
    return getattr(self._get_current_object(), name)
AttributeError: 'AnonymousUserMixin' object has no attribute 'accounts'

Traceback (most recent call last):
  File "/Users/jiemin/Documents/cmu/tasks/task06_SoftwareDesign/back-end/obs-v2/devobs/views.py", line 140, in transfer_funds
    from_account = g.user.accounts.filter_by(Account.account_num == fromacnt)
TypeError: filter_by() takes exactly 1 argument (2 given)

Traceback (most recent call last):
  File "/Users/jiemin/Documents/cmu/tasks/task06_SoftwareDesign/back-end/obs-v2/devobs/views.py", line 143, in transfer_funds
    if from_account.balance - amt >= 0:
AttributeError: 'BaseQuery' object has no attribute 'balance'

Traceback (most recent call last):
  File "/Users/jiemin/Documents/cmu/tasks/task06_SoftwareDesign/back-end/obs-v2/devobs/views.py", line 143, in transfer_funds
    if from_account.balance - amt >= 0:
TypeError: unsupported operand type(s) for -: 'long' and 'unicode'

Traceback (most recent call last):
  File "/Users/jiemin/Documents/cmu/tasks/task06_SoftwareDesign/back-end/obs-v2/devobs/views.py", line 144, in transfer_funds
    from_account.balance -= amt
TypeError: unsupported operand type(s) for -=: 'long' and 'unicode'

Traceback (most recent call last):
  File "/Users/jiemin/Documents/cmu/tasks/task06_SoftwareDesign/back-end/obs-v2/devobs/views.py", line 148, in transfer_funds
    db.session.commit()
  File "/Users/jiemin/Documents/cmu/tasks/task06_SoftwareDesign/back-end/obs-v2/flask-env/lib/python2.7/site-packages/sqlalchemy/orm/scoping.py", line 157, in do
    return getattr(self.registry(), name)(*args, **kwargs)
  File "/Users/jiemin/Documents/cmu/tasks/task06_SoftwareDesign/back-end/obs-v2/flask-env/lib/python2.7/site-packages/sqlalchemy/orm/session.py", line 921, in commit
    self.transaction.commit()
  File "/Users/jiemin/Documents/cmu/tasks/task06_SoftwareDesign/back-end/obs-v2/flask-env/lib/python2.7/site-packages/sqlalchemy/orm/session.py", line 461, in commit
    self._prepare_impl()
  File "/Users/jiemin/Documents/cmu/tasks/task06_SoftwareDesign/back-end/obs-v2/flask-env/lib/python2.7/site-packages/sqlalchemy/orm/session.py", line 441, in _prepare_impl
    self.session.flush()
  File "/Users/jiemin/Documents/cmu/tasks/task06_SoftwareDesign/back-end/obs-v2/flask-env/lib/python2.7/site-packages/sqlalchemy/orm/session.py", line 2192, in flush
    self._flush(objects)
  File "/Users/jiemin/Documents/cmu/tasks/task06_SoftwareDesign/back-end/obs-v2/flask-env/lib/python2.7/site-packages/sqlalchemy/orm/session.py", line 2312, in _flush
    transaction.rollback(_capture_exception=True)
  File "/Users/jiemin/Documents/cmu/tasks/task06_SoftwareDesign/back-end/obs-v2/flask-env/lib/python2.7/site-packages/sqlalchemy/util/langhelpers.py", line 66, in __exit__
    compat.reraise(exc_type, exc_value, exc_tb)
  File "/Users/jiemin/Documents/cmu/tasks/task06_SoftwareDesign/back-end/obs-v2/flask-env/lib/python2.7/site-packages/sqlalchemy/orm/session.py", line 2276, in _flush
    flush_context.execute()
  File "/Users/jiemin/Documents/cmu/tasks/task06_SoftwareDesign/back-end/obs-v2/flask-env/lib/python2.7/site-packages/sqlalchemy/orm/unitofwork.py", line 389, in execute
    rec.execute(self)
  File "/Users/jiemin/Documents/cmu/tasks/task06_SoftwareDesign/back-end/obs-v2/flask-env/lib/python2.7/site-packages/sqlalchemy/orm/unitofwork.py", line 548, in execute
    uow
  File "/Users/jiemin/Documents/cmu/tasks/task06_SoftwareDesign/back-end/obs-v2/flask-env/lib/python2.7/site-packages/sqlalchemy/orm/persistence.py", line 181, in save_obj
    mapper, table, insert)
  File "/Users/jiemin/Documents/cmu/tasks/task06_SoftwareDesign/back-end/obs-v2/flask-env/lib/python2.7/site-packages/sqlalchemy/orm/persistence.py", line 835, in _emit_insert_statements
    execute(statement, params)
  File "/Users/jiemin/Documents/cmu/tasks/task06_SoftwareDesign/back-end/obs-v2/flask-env/lib/python2.7/site-packages/sqlalchemy/engine/base.py", line 945, in execute
    return meth(self, multiparams, params)
  File "/Users/jiemin/Documents/cmu/tasks/task06_SoftwareDesign/back-end/obs-v2/flask-env/lib/python2.7/site-packages/sqlalchemy/sql/elements.py", line 263, in _execute_on_connection
    return connection._execute_clauseelement(self, multiparams, params)
  File "/Users/jiemin/Documents/cmu/tasks/task06_SoftwareDesign/back-end/obs-v2/flask-env/lib/python2.7/site-packages/sqlalchemy/engine/base.py", line 1053, in _execute_clauseelement
    compiled_sql, distilled_params
  File "/Users/jiemin/Documents/cmu/tasks/task06_SoftwareDesign/back-end/obs-v2/flask-env/lib/python2.7/site-packages/sqlalchemy/engine/base.py", line 1189, in _execute_context
    context)
  File "/Users/jiemin/Documents/cmu/tasks/task06_SoftwareDesign/back-end/obs-v2/flask-env/lib/python2.7/site-packages/sqlalchemy/engine/base.py", line 1402, in _handle_dbapi_exception
    exc_info
  File "/Users/jiemin/Documents/cmu/tasks/task06_SoftwareDesign/back-end/obs-v2/flask-env/lib/python2.7/site-packages/sqlalchemy/util/compat.py", line 203, in raise_from_cause
    reraise(type(exception), exception, tb=exc_tb, cause=cause)
  File "/Users/jiemin/Documents/cmu/tasks/task06_SoftwareDesign/back-end/obs-v2/flask-env/lib/python2.7/site-packages/sqlalchemy/engine/base.py", line 1182, in _execute_context
    context)
  File "/Users/jiemin/Documents/cmu/tasks/task06_SoftwareDesign/back-end/obs-v2/flask-env/lib/python2.7/site-packages/sqlalchemy/engine/default.py", line 470, in do_execute
    cursor.execute(statement, parameters)
  File "/Users/jiemin/Documents/cmu/tasks/task06_SoftwareDesign/back-end/obs-v2/flask-env/lib/python2.7/site-packages/MySQLdb/cursors.py", line 205, in execute
    self.errorhandler(self, exc, value)
  File "/Users/jiemin/Documents/cmu/tasks/task06_SoftwareDesign/back-end/obs-v2/flask-env/lib/python2.7/site-packages/MySQLdb/connections.py", line 36, in defaulterrorhandler
    raise errorclass, errorvalue
OperationalError: (_mysql_exceptions.OperationalError) (1292, "Incorrect datetime value: '<type 'datetime.datetime'>' for column 'time' at row 1") [SQL: u'INSERT INTO transfer (from_account, to_account, amount, time) VALUES (%s, %s, %s, %s)'] [parameters: (u'88776655', u'99887766', 4, <type 'datetime.datetime'>)]

Traceback (most recent call last):
  File "/Users/jiemin/Documents/cmu/tasks/task06_SoftwareDesign/back-end/obs-v2/devobs/views.py", line 147, in transfer_funds
    db.session.add(Transfer(from_account=fromacnt, to_account=toacnt, amount=amt, time=datetime.now().strftime('%Y-%m-%d %H:%M:%S')))
AttributeError: 'module' object has no attribute 'now'

Traceback (most recent call last):
  File "/Users/jiemin/Documents/cmu/tasks/task06_SoftwareDesign/back-end/obs-v2/devobs/views.py", line 147, in transfer_funds
    db.session.add(Transfer(from_account=fromacnt, to_account=toacnt, amount=amt, time=datetime.datetime.strftime('%Y-%m-%d %H:%M:%S')))
TypeError: descriptor 'strftime' requires a 'datetime.date' object but received a 'str'

Traceback (most recent call last):
  File "/Users/jiemin/Documents/cmu/tasks/task06_SoftwareDesign/back-end/obs-v2/devobs/views.py", line 137, in transfer_funds
    amt = int(request.form.get('amount'))
ValueError: invalid literal for int() with base 10: ''

Traceback (most recent call last):
  File "/Users/jiemin/Documents/cmu/tasks/task06_SoftwareDesign/back-end/obs-v2/devobs/views.py", line 142, in transfer_funds
    print(g.user.accounts)
  File "/Users/jiemin/Documents/cmu/tasks/task06_SoftwareDesign/back-end/obs-v2/flask-env/lib/python2.7/site-packages/werkzeug/local.py", line 347, in __getattr__
    return getattr(self._get_current_object(), name)
AttributeError: 'AnonymousUserMixin' object has no attribute 'accounts'

